<mujoco model="arx_default">
  <compiler angle="radian" meshdir="assets"/>

  <asset>
    <mesh name="link6" file="link6.STL"/>
  </asset>

  <worldbody>
    <body name="link6" pos="0.02845 0 0.0825" quat="-3.67321e-06 -1 0 0">
      <inertial pos="0.05 0 0" quat="0.485149 0.514422 -0.514422 0.485149" mass="0.581" diaginertia="0.000450586 0.00029 0.000279414"/>
      <joint name="joint6" pos="0 0 0" axis="1 0 0" range="-1.57 1.57" actuatorfrcrange="-100 100"/>
      <geom type="mesh" rgba="0.89804 0.91765 0.92941 1" mesh="link6"/>
      <site name="tcp_site" pos="0.0 0.0 0.0" quat="1 0 1 0" size="0.005" rgba="1 0 0 1"/>
      <site name="grasp_site" pos="0.1498 0.0 0.0" quat="1 0 1 0" size="0.005" rgba="0 1 0 1"/>
    </body>
  </worldbody>
</mujoco>
