<mujoco model="no_gripper">
  <compiler angle="radian"/>

  <worldbody>
    <body name="link_6" pos="0 0.0353 0.0395" quat="1 -1 0 0">
      <inertial pos="0 0 0" mass="1e-6" diaginertia="1e-9 1e-9 1e-9"/>
      <joint name="joint6" pos="0 0 0" axis="0 0 1" range="-2.0944 2.0944" actuatorfrcrange="-10 10"/>
      <site name="tcp_site" pos="0 0 0" quat="1 0 0 -1" size="0.005" rgba="1 0 0 1"/>
      <site name="grasp_site" pos="0 0 0.1347" quat="1 0 0 -1" size="0.005" rgba="0 1 0 1"/>
    </body>
  </worldbody>
</mujoco>
